   link                              ok
 aovpn-ras                           getting addresses
 vpn-ras
 vpn-ras                             checking link
Traceback (most recent call last):
  File "/usr/lib/python3.11/site-packages/libifstate/wireguard/__init__.py", line 56, in apply
 vpn-ras                               ifname: vpn-ras == vpn-ras
    state = self.wg.get_interface(
            ^^^^^^^^^^^^^^^^^^^^^^
  File "/usr/lib/python3.11/site-packages/wgnlpy/wireguard.py", line 35, in get_interface
 vpn-ras                               state: up == up
    return WireGuardInfo(messages, spill_private_key, spill_preshared_keys)
           ^^^^^^^^^^^^^^^^^^^^^^^^^^^^^^^^^^^^^^^^^^^^^^^^^^^^^^^^^^^^^^^^
  File "/usr/lib/python3.11/site-packages/wgnlpy/wireguardinfo.py", line 38, in __init__
    assert peer.public_key not in self.peers
 vpn-ras                               kind: None == physical
           ^^^^^^^^^^^^^^^^^^^^^^^^^^^^^^^^^
AssertionError

During handling of the above exception, another exception occurred:

Traceback (most recent call last):
  File "/usr/bin/ifstatecli", line 33, in <module>
    sys.exit(load_entry_point('ifstate==1.11.7', 'console_scripts', 'ifstatecli')())
             ^^^^^^^^^^^^^^^^^^^^^^^^^^^^^^^^^^^^^^^^^^^^^^^^^^^^^^^^^^^^^^^^^^^^^^
  File "/usr/lib/python3.11/site-packages/ifstate/ifstate.py", line 210, in main
    ifs_config.ifs.apply()
 vpn-ras                               address: 00:50:56:ad:8b:af == 00:50:56:ad:8b:af
  File "/usr/lib/python3.11/site-packages/libifstate/__init__.py", line 321, in apply
    self._apply(True, vrrp_type, vrrp_name, vrrp_state)
  File "/usr/lib/python3.11/site-packages/libifstate/__init__.py", line 511, in _apply
 vpn-ras                               master: 4 == 4
    self._apply_iface(do_apply, self.root_netns, link_dep, by_vrrp, vrrp_type, vrrp_name, vrrp_state)
  File "/usr/lib/python3.11/site-packages/libifstate/__init__.py", line 602, in _apply_iface
    netns.wireguard[ifname].apply(do_apply)
 vpn-ras                             no sysctl settings
  File "/usr/lib/python3.11/site-packages/libifstate/wireguard/__init__.py", line 60, in apply
    self.iface, err.args[1]))
                ~~~~~~~~^^^
IndexError: tuple index out of range
   link                              ok
